# 에러 처리(Error Handling)

신뢰성(reliability)에 대한 러스트의 서약(commitment)은 에러(error) 처리로 확장한다. 러스트는 어려분에게 어떤 오류 가능성을 인정하고 여러분의 코드를 컴파일하기 전에 몇 가지 조치(action)를 취하도록 요구한다. 여러분이 에러들을 발견해 여러분의 코드를 제품(production)으로 배포하기 전에 적절하게 이 에러들을 처리할(handling) 것이라는 이런 요구가 여러분의 프로그램을 더 탄탄한(robust)헤게 만든다.

러스트는 에러를 ‘회복 가능한(recoverable)’ 에러와 ‘회복 불가능한(unrecoverble)’ 에러로 구분한다. ‘회복 가능한(recoverable)’ 에러는, 예를 들어 파일 읽기와 같은 것는, 합리적으로 사용자에게 그 문제를 보고하고 그 과정을 다시 하도록 요청할 수 있다. ‘회복 불가능한(unrecoverble)’ 에러는 예를 들어 배열(array)끝 너머에 있는 위치하는 것에 접근(access)하려고 시도하는 것과 같은 버그(bugs) 증상을 있다. 대 부분의 프로그래밍 언어는 이 두 가지 에러를 구분하지 않고, 예외(exception) 같은 메커니즘을 이용해서 처리한다. 그러나 러스트에는 예외라는 개념이 없다. 대신 ‘회복 불가능한(unrecoverble)’ 에러를 위하여 `Result<T, E>` 타임을 가지고 있고, 프로그램이 회복 불가능한(unrecoverble)’ 에러를 접하게 되면 실행(execution)을 멈추는 `panic!`이라는 매크로를 가지고 있다.

## `panic!` 매크로를 이용한 ‘회복 불가능한(unrecoverble)’ 에러 에러 처리

`panic!` 매크로를 실행하면, 여러분의 프로그램은 실패 메세지를 출력하고, 스택을 풀고 정리한 다음, 종료할 것입니다. 프로젝트를 하나 만든 다음 이 패크로를 실행해 보자.

```bash
cd ..
# ~/git/rust/projects
cargo new panic_eg
cd panic_eg
```

코드는 다음과 같다. 아주 단순하다. `println!("Hello, world!");`을 지우고 아래와 같이 패크로를 추가하면 된다.

```rust
fn main() {
    panic!("crash and burn!");
}
```

`cargo run`으로 컴파일하고 실행해보자. 아래 메세지를 보면 마지막 두 줄이 에러 메세지이다. 첫 번째 줄은 패닉 메세지와 패닉이 발생한 소스 코드 위치를 출력한다.

```rust
❯ cargo run
   Compiling panic_eg v0.1.0
    Finished dev [unoptimized + debuginfo] target(s) in 2.22s
     Running `target/debug/panic_eg`
thread 'main' panicked at 'crash and burn!', src/main.rs:2:5
note: run with `RUST_BACKTRACE=1` environment variable to display a backtrace
```

### `panic!` 역추적(backtrace) 사용하기

앞에서 설펴보지 않은 두 번째 줄을 살펴보자. 이번에는 코드에 버그가 있어서 `panic!` 매크로가 호출되는 예를 살펴보겠다. 앞에서 이야기했던 배열 버그를 만들어 보자.

```rust
fn main(){
    let v = vec![1,2,3];
    
    v[99];
}
```

아래와 같이 실행하면 다음과 같다.

```bash
❯ cargo run
   Compiling panic_eg v0.1.0
    Finished dev [unoptimized + debuginfo] target(s) in 0.40s
     Running `target/debug/panic_eg`
thread 'main' panicked at 'index out of bounds: the len is 3 but the index is 99', src/main.rs:4:5
note: run with `RUST_BACKTRACE=1` environment variable to display a backtrace
```

에러를 표시하는 부분에서 첫 번째 줄은 어디서 패닉이 발생했는지, 그 원인을 알려주고 있다. 배열의 길이가 3개인데, 그 이상의 값에 접근하려고 해서 패닉이 발생했다는 것을 알려주고 있다. C 언어에서 배열의 길이 이상을 읽으려는 이런 시도가 '정의 안 한(undefined)' 행동(behavior)이다.

> You might get whatever is at the location in memory that would correspond to that element in the data structure, even though the memory doesn’t belong to that structure. This is called a buffer overread and can lead to security vulnerabilities if an attacker is able to manipulate the index in such a way as to read data they shouldn’t be allowed to that is stored after the data structure.

이런 종류의 취약성(vulnerability)에서 여러분의 프로그램을 보호하기 위해서, 만약 여러분이 존재하지 않는 인덱스(index)의 값을 읽으려고 시도한다면 러스트는 위에서와 같이 실행을 중단하고 '계속 진행하기를 거부한다(refuse to continue)'.

그러면 이제 두 번째 줄을 살펴보자. 두 번째 줄인 노트(note)는 환경 변수 `RUST_BACKTRACE`을 이용하면 어디서 에러가 발생했는지 추적할 수 있다. `RUST_BACKTRACE=1 cargo run`와 같이 하면 역추적할 수 있다. 참고로 `RUST_BACKTRACE=full`을 사용하면 좀 더 자세한 내용을 볼 수 있다. 다음 실행 결과이다.

```zsh
RUST_BACKTRACE=1 cargo run
    Finished dev [unoptimized + debuginfo] target(s) in 0.00s
     Running `target/debug/panic_eg`
thread 'main' panicked at 'index out of bounds: the len is 3 but the index is 99', src/main.rs:4:5
stack backtrace:
   0: rust_begin_unwind
             at /rustc/c8dfcfe046a7680554bf4eb612bad840e7631c4b/library/std/src/panicking.rs:515:5
   1: core::panicking::panic_fmt
             at /rustc/c8dfcfe046a7680554bf4eb612bad840e7631c4b/library/core/src/panicking.rs:92:14
   2: core::panicking::panic_bounds_check
             at /rustc/c8dfcfe046a7680554bf4eb612bad840e7631c4b/library/core/src/panicking.rs:69:5
   3: <usize as core::slice::index::SliceIndex<[T]>>::index
             at /rustc/c8dfcfe046a7680554bf4eb612bad840e7631c4b/library/core/src/slice/index.rs:184:10
   4: core::slice::index::<impl core::ops::index::Index<I> for [T]>::index
             at /rustc/c8dfcfe046a7680554bf4eb612bad840e7631c4b/library/core/src/slice/index.rs:15:9
   5: <alloc::vec::Vec<T,A> as core::ops::index::Index<I>>::index
             at /rustc/c8dfcfe046a7680554bf4eb612bad840e7631c4b/library/alloc/src/vec/mod.rs:2432:9
   6: panic_eg::main
             at ./src/main.rs:4:5
   7: core::ops::function::FnOnce::call_once
             at /rustc/c8dfcfe046a7680554bf4eb612bad840e7631c4b/library/core/src/ops/function.rs:227:5
note: Some details are omitted, run with `RUST_BACKTRACE=full` for a verbose backtrace.
```

결과는 사용 환경에 따라 많이 달라질 수 있다. 결과 내용이 많지만, 6번째에서 `at ./src/main.rs:4:5`이라고 알려주고 있으니 4번재 줄에서 5번째 줄에서 문제가 발견되었다는 것을 알 수 있다. 우리가 일부러 에러를 발생시킨 곳이다. 4번째 줄에 있는 `v[99];`을 적절히 수정하면 문제를 해결할 수 있겠다.

## `Result`으로 회복할 수 있는 에러

대부분의 에러는 그 프로그램을 완전히(entirely) 종료할 만큼 심각(serious)하지 않다. 예를 들어 파일을 열려고 하는 데 해당 파일이 없어서 파일을 여는 작업에 실패하면 프로그램을 종료하는 대신 새 파일을 생성해주면 된다.

앞에서 살펴본 것처럼 `Result` 열거형은 아래와 같이 `Ok`과 `Err`이라는 열것값을 정의하고 있다.

```rust
enum Result<T, E> {
    Ok(T),
    Err(E),
}
```

여기서 `<T, E>`은 아직 배우지 않은 제네릭에 매개 변수이다. 나중에 살펴보기로 하고, 현재는 `T`는 작업에 성공한 경우에 `Ok` 열것값으로 반환할 값의 타입(type)을 나타내는 것이고 `E`는 작업에 실패한 경우에 `Err` 열것값으로 반환할 값의 타입(type)을 나타내는 것이라고 이해하면 되겠다. 아래에서 실습할 것이다. 우선 파일을 여는 코드를 작성해보자. 별도의 프로젝트를 아래와 같이 만들어 진행하겠다.

```bash
cd ..
# ~/git/rust/projects
cargo new file_read_panic
cd file_read_panic
```

윗 프로젝트에서 `/src/main.rs`에 `hello.txt`을 여는 코드를 다음과 같이 작성해보자. 원래는 `let f = File::open("hello.txt");`과 같이 하면 되지만, 그냥 `f:u32`처럼 `f`에 임의 타입을 지정해서 에러를 만들어 보자.

```rust
use std::fs::File;

fn main() {
    let f:u32 = File::open("hello.txt");
}
```

컴파일하고 실행하면 다음과 같다.

```bash
❯ cargo run
   Compiling file_read_panic v0.1.0
error[E0308]: mismatched types
 --> src/main.rs:4:18
  |
4 |     let f: u32 = File::open("hello.txt");
  |            ---   ^^^^^^^^^^^^^^^^^^^^^^^ expected `u32`, found enum `Result`
  |            |
  |            expected due to this
  |
  = note: expected type `u32`
             found enum `Result<File, std::io::Error>`

For more information about this error, try `rustc --explain E0308`.
error: could not compile `file_read_panic` due to previous error
```

예측한 것처럼 에러가 발생했다. 노트(note)를 보면 우리가 `f`를 `u32`이라고 예상했지만, `Result<File, std::io::Error>`이라는 열거형 타입을 발견했다고 친절하게 알려준다. 앞에서 살펴본 `<T, E>`에서 `T`는`File`이고, `E`는 `std::io::Erro`이 되는 것이다. 즉 `File::open`이 성공하는 경우에는, 변수 `f` 안에 값은 파일 핸들(handle)을 포함하고 있는 `OK`의 인스턴스가 될 것이고, 실패하는 경우에는, 변수 `f` 안에 값은 발생한 에러의 종류에 대한 더 많은 정보를 포함하고 있는 `Err`의 인스턴스가 될 것이다.

`File::open`의 성공 또는 실패이라는 경우에 따라 따라 다른 행동(actions)을 하려면 코드를 다음과 같이 `match`를 이용해 코드를 작성하면 된다.

```rust
use std::fs::File;

fn main() {
    let f = File::open("hello.txt");

    let f = match f {
        Ok(file) => file,
        Err(error) => {
            panic!("파일 열기 실패: {:?}", error);
        }
    };
}
```

`Option` 열거자(enum)처럼, `Result` 열거자와 `Result`의 열것값도 전주(prelude)가 자동으로 '범위 안으로 가져온다(brought into scope)'. 그래서 `Ok`과 `Err` 앞에 `Result::`을 명시할 필요가 없다. 그냥 위에서처럼 코드를 작성하면 된다. 이렇게 작성하면, 결괏값이 `Ok`이면 `hello.txt` 파일을 읽고 처리할 것이며, `Err`이면 `panic!` 매크로를 실행해 `파일 열기 실패:`이라는 문자열 뒤에 에러 내용을 표시할 것이다. 컴파일하고 실행해보자.

```rust
cargo run
   Compiling file_read_panic v0.1.0
warning: unused variable: `f`
 --> src/main.rs:6:9
  |
6 |     let f = match f {
  |         ^ help: if this is intentional, prefix it with an underscore: `_f`
  |
  = note: `#[warn(unused_variables)]` on by default

warning: `file_read_panic` (bin "file_read_panic") generated 1 warning
    Finished dev [unoptimized + debuginfo] target(s) in 0.43s
     Running `target/debug/file_read_panic`
thread 'main' panicked at '파일 열기 실패: Os { code: 2, kind: NotFound, message: "No such file or directory" }', src/main.rs:9:13
note: run with `RUST_BACKTRACE=1` environment variable to display a backtrace
```

실행 결과를 살펴보면 정확하게 어떤 것이 잘못된 것인지 정확하게 알려주고 있다.

### 다른 에러들을 매칭하기(Matching on Different Errors)

앞 코드는 실행을 실패한 원인과 상관없이 무조건 `panic!` 매크로를 호출한다. 그렇게 하지 말고 그 실패 원인에 따라 다르게 작동하도록 코드를 수정해보자. `File::open`가 `hello.txt` 파일을 여는데 실패했다면, `hello.txt`이라는 이름으로 파일을 만들고 이 파일의 핸들(handle)를 반환한다. 만약 `File::open`가 다른 이유로 실패했다면, 앞의 코드와 마찬가지로 `panic!` 매크로를 호출한다.

```rust
use std::fs::File;
use std::io::ErrorKind;

fn main() {
    let f = File::open("hello.txt");

    let f = match f {
        Ok(file) => file,
        Err(error) => match error.kind() {
            ErrorKind::NotFound => match File::create("hello.txt") {
                Ok(fc) => fc,
                Err(e) => panic!("파일 생성 실패: {:?}", e),
            },
            other_error => panic!("파일 열기 실패: {:?}", other_error),
        },
    };
}
```

윗 코드를 컴파일하고 실행하면 다음과 같다.

```bash
cargo run
warning: unused variable: `f`
 --> src/main.rs:7:9
  |
7 |     let f = match f {
  |         ^ help: if this is intentional, prefix it with an underscore: `_f`
  |
  = note: `#[warn(unused_variables)]` on by default

warning: `file_read_panic` (bin "file_read_panic") generated 1 warning
    Finished dev [unoptimized + debuginfo] target(s) in 0.00s
     Running `target/debug/file_read_panic`
```

처음에 나오는 경고(warning)는 변수 `f`를 사용하지 않아서 발생한 것이니 신경쓸 필요가 없다. `File::open` 메세트가 반환하는 `Err` 열것값에 저장되어 있는 값의 타입은 표준 라이브러리에 정의되어 있는 구조체인 `io::Error`이다. 이 구조체는 `kind` 메소드를 갖고 있는데 이것은 우리가 `io::ErrorKind`의 값을 갖기 위해 호출할 수 있는 메소드이다. `io::ErrorKind` 열거자도 표준 라이브러리에서 제공하고 있으며, `io` 기능(operation)에서 일어날 수 있는 다른 종류의 에러를 나타내는(representing) 열것값들을 가진다. 우리가 사용하려는 것은 열것값은 `ErrorKind::NotFound`이고, 이것은 우리가 읽으려는 파일이 아직 존재하지도 않다는 것을 알리는(indicates) 열거자이다. 그래서 `match f`한 다음 다시, 그 안에 중첩하여 `match error.kind()`을 한다.

첫 번째 `match`문인 `match f`에 포함된 중괄호에서는 파일이 있은 것을 그대로 진행하고 에러가 발생하면, 두 번째 `match`문인 `match error.kind()` 포함된 중괄호를 진행한다. 이 두 번째에서는 `error.kind()`메소드가 반환한 값이 `ErrorKind::NotFound`의 열것값인지 확인한다. 만약 확인한 것이 맞다면, `File::create`을 가지고 파일을 생성하려고 시도한다. 그러나 `File::create` 또한 실패하는 경우, 우리는 세 번재 `match` 문인 `match File::create("hello.txt")`에 포함된 중괄호에서 `panic!` 메크로를 호출하게 된다. 물론 두 번째 `match`문인 `match error.kind()`에서도 `panic!` 메크로를 호출하고 있다.

이처럼 `match` 문은 매우 유용하지만, 그러나 또한 매우 원시적(primitive)이다. 13장에서 우리는 클로저(closures)를 배울 것이다. `Result<T, E>` 타임은 많은 메소드를 가지고 있으며, 이 메소드는 클로저를 수용하고 있으며, `match` 문을 사용하는 것도 구현되어 있다. 이러한 방법들을 사용하면 코드를 더 간결하게 만들어 준다.

더 노련한 '러스트 사용자(Rustacean)'은 다음과 같이 작성할 것이다.

```rust
use std::fs::File;
use std::io::ErrorKind;

fn main() {
    let f = File::open("hello.txt").unwrap_or_else(|error| {
        if error.kind() == ErrorKind::NotFound {
            File::create("hello.txt").unwrap_or_else(|error| {
                panic!("파일을 생성하는데 문제 발생: {:?}", error);
            })
        } else {
            panic!("파일을 여는데 문제 발생: {:?}", error);
        }
    });
}
```

이 코드는 앞의 코드와 정확하게 같은 일을 한다. 그러나 `match` 문은 없다.

### 에러 발생 시 패닉을 발생하는 더 빠른 방법: `unwrap`과 `expect`

`match`로 작업해도 충분하지만, 조금 장황하며 의도대로(intent) 항상 잘 통하지(communicate) 않는다. `Result<T, E>` 타입은 다양한 업무(tasks)에 사용할 수 있는 많은 조력자(helper) 메소드를 가지고 있다. 그 중의 하나가 `unwrap()`이라는 메소드이고 위에서 사용한 `match` 문과 정확하게 똑같은 것을 구현한 것이다. 만약 `unwrap()`: `Result` 값이 `OK` 열것값이면, `OK` 열것값에 저장된 값을 리턴하고, `Err` 열것값이라면, `panic!` 매크로를 호출한다.

```rust
use std::fs::File;

fn main() {
    let f = File::open("hello.txt").unwrap();
}
```

`hello.txt` 파일이 없는 상태에서 위 코드를 실행하면 바로 다음과 같이 `panic!` 매크로를 실행하고 에러 메세지를 보여준다.

```bash
❯ cargo run╯
   Compiling file_read_panic v0.1.0
warning: unused variable: `f`
 --> src/main.rs:4:9
  |
4 |     let f = File::open("hello.txt").unwrap();
  |         ^ help: if this is intentional, prefix it with an underscore: `_f`
  |
  = note: `#[warn(unused_variables)]` on by default

warning: `file_read_panic` (bin "file_read_panic") generated 1 warning
    Finished dev [unoptimized + debuginfo] target(s) in 0.90s
     Running `target/debug/file_read_panic`
thread 'main' panicked at 'called `Result::unwrap()` on an `Err` value: Os { code: 2, kind: NotFound, message: "No such file or directory" }', src/main.rs:4:37
note: run with `RUST_BACKTRACE=1` environment variable to display a backtrace
```

또다른 `expect()`는 `unwrap()`와 비슷하지만 `panic!` 매크로 에러 메세지를 우리가 선택할 수 있게 해준다.

```rust
use std::fs::File;

fn main() {
    let f = File::open("hello.txt").expect("파일을 열수 없습니다.");
}
```

윗 코드를 컴파일해서 실행하면 다음과 같다.

```bash
cargo run
   Compiling file_read_panic v0.1.0
warning: unused variable: `f`
 --> src/main.rs:4:9
  |
4 |     let f = File::open("hello.txt").expect("파일을 열수 없습니다.");
  |         ^ help: if this is intentional, prefix it with an underscore: `_f`
  |
  = note: `#[warn(unused_variables)]` on by default

warning: `file_read_panic` (bin "file_read_panic") generated 1 warning
    Finished dev [unoptimized + debuginfo] target(s) in 0.97s
     Running `target/debug/file_read_panic`
thread 'main' panicked at '파일을 열수 없습니다.: Os { code: 2, kind: NotFound, message: "No such file or directory" }', src/main.rs:4:37
note: run with `RUST_BACKTRACE=1` environment variable to display a backtrace
```

`expect()`는 `unwrap()`와 같은 일을 하지만, 위에서 볼 수 있듯이 `expect`으로 만든 에러 메세지, 위에서 "파일을 열수 없습니다."을 매개 변수처럼 사용하여 `panic!` 매크로 에러 메세지와 함께 보여주고 있다. 이를 통해 어디에서 에러가 발생했는지 쉽게 찾을 수 있다.

### 에러 전파하기(Propagating Errors)

여러분인 실패할 수 있는 것을 호출할 수 있는 것을 구현하는 함수를 작성할 때, 그 함수 안에서 에러를 처리하는(handling) 대신, 그 함수를 호출하는 코드에게 반환하여 그것을 어떻게 할 것인지 결정할 수도 있다. 이것은 에러 **전파(propagating)**라고 알려져 있으며, 호출하는 함수에게 더 많은  지배력(control)을 제공하게 되어, 이를 통해 에러를 어떻게 다뤄야 하는지에 대한 방법에 '영향을 주는(dictates)' 더 많은 정보와 논리를 갖게 해준다.

우리가 `Hello.txt`이라는 파일에서 사용자 이름을 읽으려고 한다고 해보자. 이 작업을 하는 `read_username_from_file()` 함수는 아래와 같이 해당 파일이 없는 경우에는 자신을 호출한 함수로 에러를 반환한다.

```rust
use std::fs::File;
use std::io;
use std::io::Read;

fn main() {
    let temp = read_username_from_file();
    println!("{:?}", temp);
}

fn read_username_from_file() -> Result<String, io::Error> {
    let f = File::open("Hello.txt");

    let mut f = match f {
        Ok(file) => file,
        Err(e) => return Err(e),
    };

    let mut s = String::new();

    match f.read_to_string(&mut s) {
        Ok(_) => Ok(s),
        Err(e) => Err(e),
    }
}
```

이 함수는 `Result<String, io::Error>`이라는 타입으로 반환한다는 의미인데, 이는 `Result<T, E>`의 값으로 반환한다는 것이며, 이는 제네릭 매개변수 `T`는 `String`이라는 구체적인(concrete) 타입으로 제네릭 매개변수 `E`는 `io::Error`이라는 구체적인(concrete) 타입으로 채워 넣게 된다. 이 함수가 문제없이 작동한다면, 파일에서 사용자 이름을 읽어 `String`으로 타입으로 저장한 값을 `Ok` 값으로 반환할 것이다. 만약 이 함수가 어떤 문제에 부닥친다면(encounter), 이 함수를 호출한 코드는 그 문제에 대한 더 많은 정보를 가지고 있는 `io::Error`의 인스턴스(instance)를 가지고 있는 `Err` 값을 반환받을 것이다. 이 함수의 반환 타입으로 `io::Error`을 선택한 이유는 이 함수 안에서 호출하고 있는 `File::open` 함수와 `read_to_string` 메소드 모두 실패할 수 있는데 이 두 기능(operation) 모두에서부터 반환된 에러 값의 타입이 우연히 존재하기 때문이다(We chose `io::Error` as the return type of this function because that happens to be the type of the error value returned from both of the operations we’re calling in this function’s body that might fail: `the File::open` function and the `read_to_string` method.)
`File::open`

`read_username_from_file` 함수는 `File::open` 메서드를 호출하면서 시작한다. 첫 번째 `match` 문은 앞에서 살펴본 코드들과 유사하게 작동하지만, `Err`가 발생한 경우에는 단순히 `panic!`를 호출하지 않고, 우리는 이 함수를 예정보다 일찍 반환하고 이 함수의 에러 값으로 호출하는 코드에게 `File::open`으로부터 온 에러값을 전파한다. 만약 `File::open`이 성공한다면, 우리는 변수 `f`에 파일 핸들(handle)을 저장한 다음, 진행한다.

그런 다음 `String::new`으로 변수 `s`을 새로 만들고 거기에 파일 내용을 읽어 넣기 위해 `f`안에 있는 파일 핸들(handle)을 `read_to_string` 메소드에게 요청한다. `read_to_string` 메소드가 실패할 수 있기 때문에, `File::open`이 성공하더라고, `read_to_string` 메소드도 `Result`을 반환한다. 그래서 두 번재 `match`문은 `Result`을 다루기 위해 필요한 것이다: 다시 말해 만약 `read_to_string`이 성공한다면, 본 함수는 성공하고, 우리는 이제 `Ok`안에 싸여있는 `s`안에 있는 파일에서 사용자 이름을 반환한다. 만약 `read_to_string`이 실패한다면, 우리는 `File::open`의 반환 값을 다루는 `match` 문에서 에러 값을 반환하는 것과 같은 방식으로 에러 값을 반환한다. 그러나 우리는 명시적으로 반환한다고 말할 필요가 없는데, 왜냐하면 이 함수의 마지막 표현식(expression)이기 때문이다.

`Hello.txt`이라는 파일이 없는 곳에서 윗 코드를 컴파일하고 실행하면 결과가 다음과 같다.

```bash
❯ cargo run
   Compiling file_read_panic v0.1.0
    Finished dev [unoptimized + debuginfo] target(s) in 1.35s
     Running `target/debug/file_read_panic`
Err(Os { code: 2, kind: NotFound, message: "No such file or directory" })
```

`?`연산사를 이용하면 짧게 같은 일을 하는 코드를 작성할 수 있다. 더 단순하게 만들 수도 있다. 아래 코드를 참고한다.

```rust
use std::io;
use std::io::Read;
use std::fs::File;

fn main() {
    println!("Hello, world!");
    let temp = read_username_from_file();
    println!("{:?}", temp);
    let temp = simple_read_username_from_file();
    println!("{:?}", temp);
    let temp = simple_simple_read_username_from_file();
    println!("{:?}", temp);
}

fn read_username_from_file() -> Result<String, io::Error> {
    let f = File::open("Hello.txt");

    let mut f = match f{
        Ok(file) => file,
        Err(e) => return Err(e),
    };

    let mut s = String::new();

    match f.read_to_string(&mut s) {
        Ok(_) => Ok(s),
        Err(e) => Err(e),
    }
}
//
fn simple_read_username_from_file() -> Result<String, io::Error> {
    let mut f = File::open("Hello.txt")?;
    let mut s = String::new();
    f.read_to_string(&mut s)?;
    Ok(s)
}

fn simple_simple_read_username_from_file() -> Result<String, io::Error> {
    let mut s = String::new();
    File::open("Hello.txt")?.read_to_string(&mut s)?;
    Ok(s)
}
```

최종 단축 코드

```rust
use std::io;
use std::fs;

fn main() {
    println!("Hello, world!");
    let temp = read_username_from_file();
    println!("{:?}", temp);
}

fn read_username_from_file() -> Result<String, io::Error> {
    fs::read_to_string("hello.txt")
}
```

## `panic!`쪽으로 또는 `panic!` 아닌 쪽으로

코드가 패닉에 빠지면, 회복할 방법이 존재하지 않는다. 여러분은 `panic!`을 호출할 수도 있겠다. 여러분이 `Result` 값을 반환할 것이라고 선택한다는 것은 그것을 위한 결정을 만드는 것보다 호출하는 코드에게 옵션을 제공하는 것이다. 여기서 호출하는 코드는 그 상황을 위한 적절한 방법을 회복하기 위한 시도를 선택하거나 또는 그 상황안에서 `Err` 값이 '회복 불가능(unrecoverable)'하다고 결정할 수 있어, 그 호출하는 코드가 `panic!`을 호출해서 여러분의 '회복 가능한(recoverable)' 에러를 회복 불가능한 것으로 바꾸게 된다. 그러므로 반환하는 `Result`을 반환한다는 것은 여러분이 실패할 수 있는 함수를 정의할 때 좋은 기본적인 선택이다.

드문 상황에서, `Result`을 반환하는 대신 패닉을 내는 코드를 작성하는 편이 더 적절할 수도 있다. 여기서 예를 가지고 이런 상황을 살펴보자. 물론 컴파일러는 이런 상황을 알려주는 것은 불가능하지만 인간인 여러분은 할 수 있다. 여기서 라이브러리 코드에서 패닉을 낼 것인지 말 것인지를 결정할 몇 가지 일반적인 가이드라인을 알아보겠다.

### 예제(examples), 프로토타입 코드, 그리고 테스트

예제 코드에서 `unwrap`과 같은 메소드를 호출한다는 것은 여러분이 여러분의 어플리케이션에게 에러를 처리하기를 원하는 방법을 넣을 플레이스홀더(placeholder)로서의 의미, 즉 즉 자리를 비워둔다는 의미를 갖으며, 이를 처리하는 방법은 여러분의 나머지 코드가 작동하는 것과는 다를 수도 있다는 것을 의미한다.

이와 유사하게, 에러를 어떻게 처리할지 결정할 준비가 되기 전, 프로토타이핑을 코딩할때, `unwrap`과 `expect` 메소드는 매우 쓸모가 있다. 이 함수들은 여러분의 코드를 더 강건하게(robust) 만들 준비가 되었을 때를 대비하여 깔끔한(clear) 명확한 표시들(markers)로 남겨두게 된다.

만약 테스트에서 메소드 호출이 실패한다면, 심지어 그 메소드가 기능적으로 테스트하는 중이 아니더라도, 여러분은 그 테스트 전체가 실패하기를 원할수도 있다. `panic!`은 어떤 테스트가 실패할 때 표시를 남기는 방법이기 때문에 `unwrap` 또는 `expect`을 호출한다는 것은 정확히 무엇인가 발생해야 한다는 것이다(Because `panic!` is how a test is marked as a failure, calling `unwrap` or `expect` is exactly what should happen).

### 컴파일러보다 여러분이 더많은 정보를 가지고 있는 경우

여러분이 `Result`가 `Ok` 값을 가질 것이라고 보증하는 어떤 다른 논리(logic)를 가지고 있지만, 컴파일러는 그 논리를 이해할 수 없는 것일 때는, `unwrap`를 호출하는 것 또한 적절할 것이다. 만약 여러분이 `Err` 열것값을 절대로 가질 수 없다고 코드를 손수 점검하면서 확신이 든다면, `unwrap`을 호출하는 것이 완벽하게 받아들일만 한다(it’s perfectly acceptable to call unwrap). 예를 들어보자.

```rust
use std::net::IpAddr;
let home: IpAddr = "127.0.0.1".parse().unwrap();
```

우리는 '하드 코딩된(hardcoded)' 문자열을 파싱해서 `IpAddr` 인스턴스를 생성하고 있다. 우리는 `127.0.0.1`이 타당한 IP 주소라는 것을 알 수 있으며, 그래서 여기서 `unwrap`을 사용하는 것은 받아드릴만 한다. 그러나, 하드 코딩된 것을 가진, 타당한 문자열은 파싱 메소드의 반환 타입을 변경하지는 못 한다: (편집자 주: 다시 말해) 만약 컴파일러가 이 문자열이 이미 타당한 IP 주소라고 알만큼 충분하게 영리하지 않기 때문에 `Err` 열것값이 가능성이 있다면 우리는 여전히 `Result` 값을 가지고 있으며, 컴파일러는 여전히 우리가 그 `Result`를 다루도록(handle) 할 것이다. 만약 IP 주소 문자열은 프로그램에게서 하드 코딩되서 이미 오류 가능성을 가지고 있는게 아니라 오히려 사용자로부터 온 것이라면, 우리는 단호하게 '그 대신에(instead)' 더 견고한 방법으로 `Result`을 다루기(handle)를 원할 것이다.

### 에러를 다루기 위한 가이드라인(Guidelines for Error Handling)

여러분의 코드가 결국 '나쁜 상태(bad state)'에 처하게 될 가능성이 있을 때는 여러분의 코드가 패닉을 일으키는 것이 바람직합니다. 이 문맥에서, **나쁜 상태**란 몇몇 가정이나, 보장(guarantee)이나, 계약(contract)이나 또는 불변식(invariant)이 깨진 경우, 예를 들어 '타당하지 않은(invalid)' 값들이나, 모순되는(contradictory) 값들이나, 또는 행방불명된(missing) 값들을 여러분의 코드에게 돌려줄 때 - 거기에 아래와 같은 것이 하나 또는 그 이상이 더해질 때:

- 이 나쁜 상태가 우연하게 발생된 것이라고 **예상되는** 어떤 것이 아니다.
- 이 시점 이후 여러분 코드는 이 나쁜 상태안에 있지 않다고 기대를 걸 필요가 있다.
- 여러분이 사용하는 타입 안에 이 정보를 인코딩할 좋은 방법이 없다.

만약 누군가 여러분 코드를 호출하고 '이치에 맞지 않는 값들이 지나간다면(passes in values that don’t make sense)', `panic!`을 호출해서 여러분의 라이브러리를 사용하고 있는 사람에게 그 사람의 코드 안에 버그가 있다는 것을 알려줘 개발하는 동안 이를 고칠 수 있게끔 하는 것이 최선책일 수도 있다. 이와 비슷하게, 만약 여러분이 여러분의 통제를 벗어간 외부 코드를 호출하는 중이며 이것이 여러분이 수정할(fixing) 방법이 없는 '타당하지 않은(invalid)' 상태를 반환한다면, `panic!`이 대개 적절하다(appropriate).

그러나, 실패를 예상될 때는, `panic!`을 호출하게 하는 것보다. `Result`을 반환하는 편이 더 적절하다. 예를 들어 '형식이 형편없는(malformed)' 데이터를 갖게될 파서나 여러분이 속도 제한에 도달했음을 나타내는 상태를 반환하는 HTTP 요청(request)을 포함한다. 이러한 경우들에서, `Result`를 반환한다는 것은 호출하는 코드가 처리하는 방법을 결정할 수 있어야 한다는 예상된 가능성이 오류라는 것을 알리는 것이다.

### 타당성 검사를 위한 커스텀 타입을 생성하기(Creating Custom Types for Validation)

우리가 타당한 값을 가지고 있다고 보장(ensure)하기 위해 러스트의 타입 시스템을 이용한다는 아이디어에서 한 걸음 더 나아 '타당성 검사(validation)'를 위한 커스텀 타입을 생성하는 살펴보자. 2장 추측 게임에서 우리 코드는 사용자에게 1부터 100 사이의 숫자를 추측하도록 요청한 것을 떠올려 보자. 우리는 사용자가 추측한 것을 우리의 비밀 번호와 대조하기 전에 이 사이의 숫자인지 타당성 검사를 전혀 하지 않았다; (편집자 주: 반면에) 우리는 단지 추측한 것이 양수인지 타당성 검사를 했을 뿐이다. 이 경우에, 결과는 그렇게 끔직하지(dire) 않았다: 즉 우리는 "좀 크다(Too high)"나 "좀 작다(Too low)"라는 우리 출력은 여전히 올바를 것이다. 그러나 사용자에게 타당한 추측으로 나아가도록 안내하고 사용자가, 예를 들어, 그 대신 글자를 입력했을 때를 대비하여 사용자가 영역을 넘어서 숫자를 추측할 때 다른 행동을 갖게 하는 유용한 강화도 있을 것이다.

이렇게 하기 위한 한 가지 방법은 잠재적으로 음수 입력을 허용하기 위해 오로지 `u32`만으로 하는 대신 `i32`을 추측값을 파싱하고, 그런 다음 그 추측 숫자가 영역 안에 있는지 다음과 같이 점검하는 것이다:

```rust
loop {
        // --snip--

        let guess: i32 = match guess.trim().parse() {
            Ok(num) => num,
            Err(_) => continue,
        };

        if guess < 1 || guess > 100 {
            println!("The secret number will be between 1 and 100.");
            continue;
        }

        match guess.cmp(&secret_number) {
            // --snip--
    }
```

`if` 문이 우리의 값이 영역 밖에 있는지 점검하고, 사용자에게 그 문제에 대해 말하고, `continue`를 호출해 다음 루프(loop) 반복(iteration)을 시작해 다른 추측값을 요청한다. `if` 문 이후에, 우리는 추측값과 1과 100 사이에서 추측했다고 알고 있는 비밀 숫자에 대한 비교를 진행할 수 있다.

그러나, 이것은 이상적인 해결잭은 아니다: 만약 프로그램이 오로지 1과 100 사이의 값드에서만 작동하고, 많은 함수들이 이 요구사항을 가지고 있다면, 모든 함수에서 이와 같은 점검을 하는 것은 장황할 것이다(그리고 성능에 출격을 줄 수 있다).

그 대신, 우리는 모든 곳에서 타당성 검사를 반복하는 것보다 새로운 타입을 만들어 그 타임의 인스턴스를 생성하기 위한 함수 안에 타당성 검사를 넣을 수 있다. 이 방법은, 함수가 자신의 시그니쳐(signatures)에서 새로운 타입을 사용하고 함수가 반환하는 값들을 자신 있게 사용하는데 안전하다. 다음 코드에서 `new` 함수가 1과 100 사이의 값을 받는 경우에만 `Guess`의 인스턴스를 생성하는 `Guess` 타입을 정의하는 한 가지 방법을 보여주고 있다.
